2016-07-29 15:22:23,666 aec05f2c MainThread INFO     Verbose logging to: /tmp/perfkitbenchmarker/runs/aec05f2c/pkb.log
2016-07-29 15:22:23,667 aec05f2c MainThread INFO     PerfKitBenchmarker version: unknown
2016-07-29 15:22:23,667 aec05f2c MainThread INFO     Flag values:
--rack_path=../lib/providers/Rackspace/rack
--ignore_package_requirements
--rack_profile=phileas
--csv_path=../etc/runs/Rackspace/csv/results.csv
--cloud=Rackspace
--benchmarks=iperf,fio,coremark,ping,unixbench
--rackspace_region=IAD
--iperf_runtime_in_seconds=30
--nocollapse_labels
--fio_jobfile=../lib/providers/Rackspace/config/fio.txt
--json_path=../etc/runs/Rackspace/csv/results.json
2016-07-29 15:22:24,080 aec05f2c MainThread iperf(1/5) INFO     Provisioning resources for benchmark iperf
2016-07-29 15:22:24,084 aec05f2c Thread-1 iperf(1/5) INFO     Running: ../lib/providers/Rackspace/rack servers keypair upload --name pkb-aec05f2c-1 --file /tmp/perfkitbenchmarker/runs/aec05f2c/perfkitbenchmarker_keyfile.pub --output json --profile phileas --region IAD
2016-07-29 15:22:24,085 aec05f2c Thread-2 iperf(1/5) INFO     Running: ../lib/providers/Rackspace/rack servers keypair upload --name pkb-aec05f2c-0 --file /tmp/perfkitbenchmarker/runs/aec05f2c/perfkitbenchmarker_keyfile.pub --output json --profile phileas --region IAD
2016-07-29 15:22:44,685 aec05f2c Thread-2 iperf(1/5) INFO     Running: ../lib/providers/Rackspace/rack servers instance create --name pkb-aec05f2c-0 --keypair pkb-aec05f2c-0 --flavor-id general1-1 --image-id 09de0a66-3156-48b4-90a5-1cf25a905207 --user-data /tmp/perfkitbenchmarker/runs/aec05f2c/user-data9e2OR0 --metadata owner=root --output json --profile phileas --region IAD
2016-07-29 15:22:44,685 aec05f2c Thread-1 iperf(1/5) INFO     Running: ../lib/providers/Rackspace/rack servers instance create --name pkb-aec05f2c-1 --keypair pkb-aec05f2c-1 --flavor-id general1-1 --image-id 09de0a66-3156-48b4-90a5-1cf25a905207 --user-data /tmp/perfkitbenchmarker/runs/aec05f2c/user-data7MrxWb --metadata owner=root --output json --profile phileas --region IAD
2016-07-29 15:23:06,199 aec05f2c Thread-1 iperf(1/5) INFO     Running: ../lib/providers/Rackspace/rack servers instance get --id 044d5090-59fe-4b44-a511-68d04fedaf30 --output json --profile phileas --region IAD
2016-07-29 15:23:06,442 aec05f2c Thread-2 iperf(1/5) INFO     Running: ../lib/providers/Rackspace/rack servers instance get --id 7e388133-5056-45a9-9475-6b81394df088 --output json --profile phileas --region IAD
2016-07-29 15:23:31,189 aec05f2c Thread-1 iperf(1/5) INFO     Running: ../lib/providers/Rackspace/rack servers instance get --id 044d5090-59fe-4b44-a511-68d04fedaf30 --output json --profile phileas --region IAD
2016-07-29 15:23:31,271 aec05f2c Thread-2 iperf(1/5) INFO     Running: ../lib/providers/Rackspace/rack servers instance get --id 7e388133-5056-45a9-9475-6b81394df088 --output json --profile phileas --region IAD
2016-07-29 15:23:52,568 aec05f2c Thread-2 iperf(1/5) INFO     VM: pkb-aec05f2c-0 is up and running.
2016-07-29 15:23:52,569 aec05f2c Thread-2 iperf(1/5) INFO     Running: ../lib/providers/Rackspace/rack servers instance get --id 7e388133-5056-45a9-9475-6b81394df088 --output json --profile phileas --region IAD
2016-07-29 15:23:57,070 aec05f2c Thread-1 iperf(1/5) INFO     Running: ../lib/providers/Rackspace/rack servers instance get --id 044d5090-59fe-4b44-a511-68d04fedaf30 --output json --profile phileas --region IAD
2016-07-29 15:24:12,590 aec05f2c Thread-2 iperf(1/5) ERROR    Got exception running _CreateResource: Creation of DebianBasedRackspaceVirtualMachine failed.
2016-07-29 15:24:20,389 aec05f2c Thread-1 iperf(1/5) INFO     Running: ../lib/providers/Rackspace/rack servers instance get --id 044d5090-59fe-4b44-a511-68d04fedaf30 --output json --profile phileas --region IAD
2016-07-29 15:24:33,229 aec05f2c Thread-2 iperf(1/5) INFO     Running: ../lib/providers/Rackspace/rack servers instance create --name pkb-aec05f2c-0 --keypair pkb-aec05f2c-0 --flavor-id general1-1 --image-id 09de0a66-3156-48b4-90a5-1cf25a905207 --user-data /tmp/perfkitbenchmarker/runs/aec05f2c/user-data77Nez7 --metadata owner=root --output json --profile phileas --region IAD
2016-07-29 15:24:43,431 aec05f2c Thread-1 iperf(1/5) INFO     Running: ../lib/providers/Rackspace/rack servers instance get --id 044d5090-59fe-4b44-a511-68d04fedaf30 --output json --profile phileas --region IAD
2016-07-29 15:24:53,606 aec05f2c MainThread iperf(1/5) ERROR    Exception occurred while calling PrepareVm(<BaseVirtualMachine [ip=None, internal_ip=None]>):
Traceback (most recent call last):
  File "/Users/dkheyman/dev/phileas/2016.6/lib/PerfKitBenchmarker/perfkitbenchmarker/background_tasks.py", line 234, in Run
    self.return_value = self.target(*self.args, **self.kwargs)
  File "/Users/dkheyman/dev/phileas/2016.6/lib/PerfKitBenchmarker/perfkitbenchmarker/benchmark_spec.py", line 341, in PrepareVm
    vm.Create()
  File "/Users/dkheyman/dev/phileas/2016.6/lib/PerfKitBenchmarker/perfkitbenchmarker/resource.py", line 150, in Create
    self._CreateResource()
  File "/Users/dkheyman/dev/phileas/2016.6/lib/PerfKitBenchmarker/perfkitbenchmarker/vm_util.py", line 239, in WrappedFunction
    return f(*args, **kwargs)
  File "/Users/dkheyman/dev/phileas/2016.6/lib/PerfKitBenchmarker/perfkitbenchmarker/resource.py", line 119, in _CreateResource
    self._Create()
  File "/Users/dkheyman/dev/phileas/2016.6/lib/PerfKitBenchmarker/perfkitbenchmarker/providers/rackspace/rackspace_virtual_machine.py", line 182, in _Create
    self._CreateInstance()
  File "/Users/dkheyman/dev/phileas/2016.6/lib/PerfKitBenchmarker/perfkitbenchmarker/providers/rackspace/rackspace_virtual_machine.py", line 249, in _CreateInstance
    'Following command caused the error: %s' % repr(create_cmd),)))
Error: Non-recoverable error has occurred: {u'error': u'Error while executing HTTP request for server []'}
Following command caused the error: RackCLICommand(../lib/providers/Rackspace/rack servers instance create --name pkb-aec05f2c-0 --keypair pkb-aec05f2c-0 --flavor-id general1-1 --image-id 09de0a66-3156-48b4-90a5-1cf25a905207 --user-data /tmp/perfkitbenchmarker/runs/aec05f2c/user-data77Nez7 --metadata owner=root --output json --profile phileas --region IAD)

2016-07-29 15:25:03,699 aec05f2c Thread-1 iperf(1/5) INFO     VM: pkb-aec05f2c-1 is up and running.
2016-07-29 15:25:03,699 aec05f2c Thread-1 iperf(1/5) INFO     Running: ../lib/providers/Rackspace/rack servers instance get --id 044d5090-59fe-4b44-a511-68d04fedaf30 --output json --profile phileas --region IAD
2016-07-29 15:25:23,969 aec05f2c Thread-1 iperf(1/5) INFO     Running: ../lib/providers/Rackspace/rack servers instance get --id 044d5090-59fe-4b44-a511-68d04fedaf30 --output json --profile phileas --region IAD
2016-07-29 15:25:44,256 aec05f2c Thread-1 iperf(1/5) INFO     VM: 146.20.110.240
2016-07-29 15:25:44,256 aec05f2c Thread-1 iperf(1/5) INFO     Waiting for boot completion.
2016-07-29 15:25:44,257 aec05f2c Thread-1 iperf(1/5) INFO     Running: ssh -A -p 22 perfkit@146.20.110.240 -2 -o UserKnownHostsFile=/dev/null -o StrictHostKeyChecking=no -o IdentitiesOnly=yes -o PreferredAuthentications=publickey -o PasswordAuthentication=no -o ConnectTimeout=5 -o GSSAPIAuthentication=no -o ServerAliveInterval=30 -o ServerAliveCountMax=10 -i /tmp/perfkitbenchmarker/runs/aec05f2c/perfkitbenchmarker_keyfile hostname
2016-07-29 15:25:44,638 aec05f2c Thread-1 iperf(1/5) INFO     Running: ../lib/providers/Rackspace/rack servers instance update-metadata --id 044d5090-59fe-4b44-a511-68d04fedaf30 --metadata benchmark_uid=iperf0,benchmark=iperf,perfkit_uuid=aec05f2c-cc88442a-2994-481e-ac6b-858441deea81 --output json --profile phileas --region IAD
2016-07-29 15:26:05,370 aec05f2c Thread-1 iperf(1/5) INFO     Running: ssh -A -p 22 perfkit@146.20.110.240 -2 -o UserKnownHostsFile=/dev/null -o StrictHostKeyChecking=no -o IdentitiesOnly=yes -o PreferredAuthentications=publickey -o PasswordAuthentication=no -o ConnectTimeout=5 -o GSSAPIAuthentication=no -o ServerAliveInterval=30 -o ServerAliveCountMax=10 -i /tmp/perfkitbenchmarker/runs/aec05f2c/perfkitbenchmarker_keyfile sudo lsblk -o NAME,MODEL,SIZE,TYPE,MOUNTPOINT,LABEL -n -b -P
2016-07-29 15:26:05,838 aec05f2c Thread-1 iperf(1/5) INFO     Running: ssh -A -p 22 perfkit@146.20.110.240 -2 -o UserKnownHostsFile=/dev/null -o StrictHostKeyChecking=no -o IdentitiesOnly=yes -o PreferredAuthentications=publickey -o PasswordAuthentication=no -o ConnectTimeout=5 -o GSSAPIAuthentication=no -o ServerAliveInterval=30 -o ServerAliveCountMax=10 -i /tmp/perfkitbenchmarker/runs/aec05f2c/perfkitbenchmarker_keyfile mkdir -p /tmp/pkb
2016-07-29 15:26:06,345 aec05f2c MainThread iperf(1/5) ERROR    Error during benchmark iperf
Traceback (most recent call last):
  File "/Users/dkheyman/dev/phileas/2016.6/lib/PerfKitBenchmarker/perfkitbenchmarker/pkb.py", line 470, in RunBenchmark
    DoProvisionPhase(benchmark_name, spec, detailed_timer)
  File "/Users/dkheyman/dev/phileas/2016.6/lib/PerfKitBenchmarker/perfkitbenchmarker/pkb.py", line 329, in DoProvisionPhase
    spec.Provision()
  File "/Users/dkheyman/dev/phileas/2016.6/lib/PerfKitBenchmarker/perfkitbenchmarker/benchmark_spec.py", line 264, in Provision
    vm_util.RunThreaded(self.PrepareVm, self.vms)
  File "/Users/dkheyman/dev/phileas/2016.6/lib/PerfKitBenchmarker/perfkitbenchmarker/background_tasks.py", line 613, in RunThreaded
    max_concurrency=max_concurrent_threads)
  File "/Users/dkheyman/dev/phileas/2016.6/lib/PerfKitBenchmarker/perfkitbenchmarker/background_tasks.py", line 557, in RunParallelThreads
    errors.VmUtil.ThreadException)
  File "/Users/dkheyman/dev/phileas/2016.6/lib/PerfKitBenchmarker/perfkitbenchmarker/background_tasks.py", line 532, in _RunParallelTasks
    '{0}{1}'.format(os.linesep, os.linesep.join(error_strings)))
ThreadException: The following exceptions occurred during parallel execution:
Exception occurred while calling PrepareVm(<BaseVirtualMachine [ip=None, internal_ip=None]>):
Traceback (most recent call last):
  File "/Users/dkheyman/dev/phileas/2016.6/lib/PerfKitBenchmarker/perfkitbenchmarker/background_tasks.py", line 234, in Run
    self.return_value = self.target(*self.args, **self.kwargs)
  File "/Users/dkheyman/dev/phileas/2016.6/lib/PerfKitBenchmarker/perfkitbenchmarker/benchmark_spec.py", line 341, in PrepareVm
    vm.Create()
  File "/Users/dkheyman/dev/phileas/2016.6/lib/PerfKitBenchmarker/perfkitbenchmarker/resource.py", line 150, in Create
    self._CreateResource()
  File "/Users/dkheyman/dev/phileas/2016.6/lib/PerfKitBenchmarker/perfkitbenchmarker/vm_util.py", line 239, in WrappedFunction
    return f(*args, **kwargs)
  File "/Users/dkheyman/dev/phileas/2016.6/lib/PerfKitBenchmarker/perfkitbenchmarker/resource.py", line 119, in _CreateResource
    self._Create()
  File "/Users/dkheyman/dev/phileas/2016.6/lib/PerfKitBenchmarker/perfkitbenchmarker/providers/rackspace/rackspace_virtual_machine.py", line 182, in _Create
    self._CreateInstance()
  File "/Users/dkheyman/dev/phileas/2016.6/lib/PerfKitBenchmarker/perfkitbenchmarker/providers/rackspace/rackspace_virtual_machine.py", line 249, in _CreateInstance
    'Following command caused the error: %s' % repr(create_cmd),)))
Error: Non-recoverable error has occurred: {u'error': u'Error while executing HTTP request for server []'}
Following command caused the error: RackCLICommand(../lib/providers/Rackspace/rack servers instance create --name pkb-aec05f2c-0 --keypair pkb-aec05f2c-0 --flavor-id general1-1 --image-id 09de0a66-3156-48b4-90a5-1cf25a905207 --user-data /tmp/perfkitbenchmarker/runs/aec05f2c/user-data77Nez7 --metadata owner=root --output json --profile phileas --region IAD)

2016-07-29 15:26:06,348 aec05f2c Thread-23 iperf(1/5) INFO     Running: ../lib/providers/Rackspace/rack servers instance delete --id 7e388133-5056-45a9-9475-6b81394df088 --output json --profile phileas --region IAD
2016-07-29 15:26:06,349 aec05f2c Thread-22 iperf(1/5) INFO     Running: ../lib/providers/Rackspace/rack servers instance delete --id 044d5090-59fe-4b44-a511-68d04fedaf30 --output json --profile phileas --region IAD
2016-07-29 15:26:26,949 aec05f2c Thread-23 iperf(1/5) INFO     Running: ../lib/providers/Rackspace/rack servers instance get --id 7e388133-5056-45a9-9475-6b81394df088 --output json --profile phileas --region IAD
2016-07-29 15:26:27,030 aec05f2c Thread-22 iperf(1/5) INFO     Running: ../lib/providers/Rackspace/rack servers instance get --id 044d5090-59fe-4b44-a511-68d04fedaf30 --output json --profile phileas --region IAD
2016-07-29 15:26:47,242 aec05f2c Thread-23 iperf(1/5) INFO     VM: pkb-aec05f2c-0 has been successfully deleted.
2016-07-29 15:26:47,244 aec05f2c Thread-23 iperf(1/5) INFO     Running: ../lib/providers/Rackspace/rack servers instance get --id 7e388133-5056-45a9-9475-6b81394df088 --output json --profile phileas --region IAD
2016-07-29 15:26:47,285 aec05f2c Thread-22 iperf(1/5) INFO     VM: pkb-aec05f2c-1 has been successfully deleted.
2016-07-29 15:26:47,285 aec05f2c Thread-22 iperf(1/5) INFO     Running: ../lib/providers/Rackspace/rack servers instance get --id 044d5090-59fe-4b44-a511-68d04fedaf30 --output json --profile phileas --region IAD
2016-07-29 15:27:07,264 aec05f2c Thread-23 iperf(1/5) INFO     Running: ../lib/providers/Rackspace/rack servers keypair delete --name pkb-aec05f2c-0 --output json --profile phileas --region IAD
2016-07-29 15:27:07,305 aec05f2c Thread-22 iperf(1/5) INFO     Running: ../lib/providers/Rackspace/rack servers keypair delete --name pkb-aec05f2c-1 --output json --profile phileas --region IAD
2016-07-29 15:27:27,505 aec05f2c MainThread iperf(1/5) ERROR    Benchmark 1/5 iperf (UID: iperf0) failed. Execution will continue.
2016-07-29 15:27:27,506 aec05f2c MainThread iperf(1/5) ping(2/5) INFO     Provisioning resources for benchmark ping
2016-07-29 15:27:27,509 aec05f2c Thread-32 iperf(1/5) ping(2/5) INFO     Running: ../lib/providers/Rackspace/rack servers keypair upload --name pkb-aec05f2c-3 --file /tmp/perfkitbenchmarker/runs/aec05f2c/perfkitbenchmarker_keyfile.pub --output json --profile phileas --region IAD
2016-07-29 15:27:27,510 aec05f2c Thread-33 iperf(1/5) ping(2/5) INFO     Running: ../lib/providers/Rackspace/rack servers keypair upload --name pkb-aec05f2c-2 --file /tmp/perfkitbenchmarker/runs/aec05f2c/perfkitbenchmarker_keyfile.pub --output json --profile phileas --region IAD
2016-07-29 15:27:47,531 aec05f2c Thread-33 iperf(1/5) ping(2/5) INFO     Running: ../lib/providers/Rackspace/rack servers instance create --name pkb-aec05f2c-2 --keypair pkb-aec05f2c-2 --flavor-id general1-1 --image-id 09de0a66-3156-48b4-90a5-1cf25a905207 --user-data /tmp/perfkitbenchmarker/runs/aec05f2c/user-datayM4uf6 --metadata owner=root --output json --profile phileas --region IAD
2016-07-29 15:27:47,532 aec05f2c Thread-32 iperf(1/5) ping(2/5) INFO     Running: ../lib/providers/Rackspace/rack servers instance create --name pkb-aec05f2c-3 --keypair pkb-aec05f2c-3 --flavor-id general1-1 --image-id 09de0a66-3156-48b4-90a5-1cf25a905207 --user-data /tmp/perfkitbenchmarker/runs/aec05f2c/user-data32uJqb --metadata owner=root --output json --profile phileas --region IAD
2016-07-29 15:28:07,599 aec05f2c MainThread iperf(1/5) ping(2/5) ERROR    Exception occurred while calling PrepareVm(<BaseVirtualMachine [ip=None, internal_ip=None]>):
Traceback (most recent call last):
  File "/Users/dkheyman/dev/phileas/2016.6/lib/PerfKitBenchmarker/perfkitbenchmarker/background_tasks.py", line 234, in Run
    self.return_value = self.target(*self.args, **self.kwargs)
  File "/Users/dkheyman/dev/phileas/2016.6/lib/PerfKitBenchmarker/perfkitbenchmarker/benchmark_spec.py", line 341, in PrepareVm
    vm.Create()
  File "/Users/dkheyman/dev/phileas/2016.6/lib/PerfKitBenchmarker/perfkitbenchmarker/resource.py", line 150, in Create
    self._CreateResource()
  File "/Users/dkheyman/dev/phileas/2016.6/lib/PerfKitBenchmarker/perfkitbenchmarker/vm_util.py", line 239, in WrappedFunction
    return f(*args, **kwargs)
  File "/Users/dkheyman/dev/phileas/2016.6/lib/PerfKitBenchmarker/perfkitbenchmarker/resource.py", line 119, in _CreateResource
    self._Create()
  File "/Users/dkheyman/dev/phileas/2016.6/lib/PerfKitBenchmarker/perfkitbenchmarker/providers/rackspace/rackspace_virtual_machine.py", line 182, in _Create
    self._CreateInstance()
  File "/Users/dkheyman/dev/phileas/2016.6/lib/PerfKitBenchmarker/perfkitbenchmarker/providers/rackspace/rackspace_virtual_machine.py", line 249, in _CreateInstance
    'Following command caused the error: %s' % repr(create_cmd),)))
Error: Non-recoverable error has occurred: {u'error': u'Post https://iad.servers.api.rackspacecloud.com/v2/1010949/servers: dial tcp: lookup iad.servers.api.rackspacecloud.com on 172.16.1.1:53: read udp 172.16.1.1:53: i/o timeout'}
Following command caused the error: RackCLICommand(../lib/providers/Rackspace/rack servers instance create --name pkb-aec05f2c-2 --keypair pkb-aec05f2c-2 --flavor-id general1-1 --image-id 09de0a66-3156-48b4-90a5-1cf25a905207 --user-data /tmp/perfkitbenchmarker/runs/aec05f2c/user-datayM4uf6 --metadata owner=root --output json --profile phileas --region IAD)

2016-07-29 15:28:07,600 aec05f2c MainThread iperf(1/5) ping(2/5) ERROR    Exception occurred while calling PrepareVm(<BaseVirtualMachine [ip=None, internal_ip=None]>):
Traceback (most recent call last):
  File "/Users/dkheyman/dev/phileas/2016.6/lib/PerfKitBenchmarker/perfkitbenchmarker/background_tasks.py", line 234, in Run
    self.return_value = self.target(*self.args, **self.kwargs)
  File "/Users/dkheyman/dev/phileas/2016.6/lib/PerfKitBenchmarker/perfkitbenchmarker/benchmark_spec.py", line 341, in PrepareVm
    vm.Create()
  File "/Users/dkheyman/dev/phileas/2016.6/lib/PerfKitBenchmarker/perfkitbenchmarker/resource.py", line 150, in Create
    self._CreateResource()
  File "/Users/dkheyman/dev/phileas/2016.6/lib/PerfKitBenchmarker/perfkitbenchmarker/vm_util.py", line 239, in WrappedFunction
    return f(*args, **kwargs)
  File "/Users/dkheyman/dev/phileas/2016.6/lib/PerfKitBenchmarker/perfkitbenchmarker/resource.py", line 119, in _CreateResource
    self._Create()
  File "/Users/dkheyman/dev/phileas/2016.6/lib/PerfKitBenchmarker/perfkitbenchmarker/providers/rackspace/rackspace_virtual_machine.py", line 182, in _Create
    self._CreateInstance()
  File "/Users/dkheyman/dev/phileas/2016.6/lib/PerfKitBenchmarker/perfkitbenchmarker/providers/rackspace/rackspace_virtual_machine.py", line 249, in _CreateInstance
    'Following command caused the error: %s' % repr(create_cmd),)))
Error: Non-recoverable error has occurred: {u'error': u'Post https://iad.servers.api.rackspacecloud.com/v2/1010949/servers: dial tcp: lookup iad.servers.api.rackspacecloud.com on 172.16.1.1:53: read udp 172.16.1.1:53: i/o timeout'}
Following command caused the error: RackCLICommand(../lib/providers/Rackspace/rack servers instance create --name pkb-aec05f2c-3 --keypair pkb-aec05f2c-3 --flavor-id general1-1 --image-id 09de0a66-3156-48b4-90a5-1cf25a905207 --user-data /tmp/perfkitbenchmarker/runs/aec05f2c/user-data32uJqb --metadata owner=root --output json --profile phileas --region IAD)

2016-07-29 15:28:07,604 aec05f2c MainThread iperf(1/5) ping(2/5) ERROR    Error during benchmark ping
Traceback (most recent call last):
  File "/Users/dkheyman/dev/phileas/2016.6/lib/PerfKitBenchmarker/perfkitbenchmarker/pkb.py", line 470, in RunBenchmark
    DoProvisionPhase(benchmark_name, spec, detailed_timer)
  File "/Users/dkheyman/dev/phileas/2016.6/lib/PerfKitBenchmarker/perfkitbenchmarker/pkb.py", line 329, in DoProvisionPhase
    spec.Provision()
  File "/Users/dkheyman/dev/phileas/2016.6/lib/PerfKitBenchmarker/perfkitbenchmarker/benchmark_spec.py", line 264, in Provision
    vm_util.RunThreaded(self.PrepareVm, self.vms)
  File "/Users/dkheyman/dev/phileas/2016.6/lib/PerfKitBenchmarker/perfkitbenchmarker/background_tasks.py", line 613, in RunThreaded
    max_concurrency=max_concurrent_threads)
  File "/Users/dkheyman/dev/phileas/2016.6/lib/PerfKitBenchmarker/perfkitbenchmarker/background_tasks.py", line 557, in RunParallelThreads
    errors.VmUtil.ThreadException)
  File "/Users/dkheyman/dev/phileas/2016.6/lib/PerfKitBenchmarker/perfkitbenchmarker/background_tasks.py", line 532, in _RunParallelTasks
    '{0}{1}'.format(os.linesep, os.linesep.join(error_strings)))
ThreadException: The following exceptions occurred during parallel execution:
Exception occurred while calling PrepareVm(<BaseVirtualMachine [ip=None, internal_ip=None]>):
Traceback (most recent call last):
  File "/Users/dkheyman/dev/phileas/2016.6/lib/PerfKitBenchmarker/perfkitbenchmarker/background_tasks.py", line 234, in Run
    self.return_value = self.target(*self.args, **self.kwargs)
  File "/Users/dkheyman/dev/phileas/2016.6/lib/PerfKitBenchmarker/perfkitbenchmarker/benchmark_spec.py", line 341, in PrepareVm
    vm.Create()
  File "/Users/dkheyman/dev/phileas/2016.6/lib/PerfKitBenchmarker/perfkitbenchmarker/resource.py", line 150, in Create
    self._CreateResource()
  File "/Users/dkheyman/dev/phileas/2016.6/lib/PerfKitBenchmarker/perfkitbenchmarker/vm_util.py", line 239, in WrappedFunction
    return f(*args, **kwargs)
  File "/Users/dkheyman/dev/phileas/2016.6/lib/PerfKitBenchmarker/perfkitbenchmarker/resource.py", line 119, in _CreateResource
    self._Create()
  File "/Users/dkheyman/dev/phileas/2016.6/lib/PerfKitBenchmarker/perfkitbenchmarker/providers/rackspace/rackspace_virtual_machine.py", line 182, in _Create
    self._CreateInstance()
  File "/Users/dkheyman/dev/phileas/2016.6/lib/PerfKitBenchmarker/perfkitbenchmarker/providers/rackspace/rackspace_virtual_machine.py", line 249, in _CreateInstance
    'Following command caused the error: %s' % repr(create_cmd),)))
Error: Non-recoverable error has occurred: {u'error': u'Post https://iad.servers.api.rackspacecloud.com/v2/1010949/servers: dial tcp: lookup iad.servers.api.rackspacecloud.com on 172.16.1.1:53: read udp 172.16.1.1:53: i/o timeout'}
Following command caused the error: RackCLICommand(../lib/providers/Rackspace/rack servers instance create --name pkb-aec05f2c-2 --keypair pkb-aec05f2c-2 --flavor-id general1-1 --image-id 09de0a66-3156-48b4-90a5-1cf25a905207 --user-data /tmp/perfkitbenchmarker/runs/aec05f2c/user-datayM4uf6 --metadata owner=root --output json --profile phileas --region IAD)

Exception occurred while calling PrepareVm(<BaseVirtualMachine [ip=None, internal_ip=None]>):
Traceback (most recent call last):
  File "/Users/dkheyman/dev/phileas/2016.6/lib/PerfKitBenchmarker/perfkitbenchmarker/background_tasks.py", line 234, in Run
    self.return_value = self.target(*self.args, **self.kwargs)
  File "/Users/dkheyman/dev/phileas/2016.6/lib/PerfKitBenchmarker/perfkitbenchmarker/benchmark_spec.py", line 341, in PrepareVm
    vm.Create()
  File "/Users/dkheyman/dev/phileas/2016.6/lib/PerfKitBenchmarker/perfkitbenchmarker/resource.py", line 150, in Create
    self._CreateResource()
  File "/Users/dkheyman/dev/phileas/2016.6/lib/PerfKitBenchmarker/perfkitbenchmarker/vm_util.py", line 239, in WrappedFunction
    return f(*args, **kwargs)
  File "/Users/dkheyman/dev/phileas/2016.6/lib/PerfKitBenchmarker/perfkitbenchmarker/resource.py", line 119, in _CreateResource
    self._Create()
  File "/Users/dkheyman/dev/phileas/2016.6/lib/PerfKitBenchmarker/perfkitbenchmarker/providers/rackspace/rackspace_virtual_machine.py", line 182, in _Create
    self._CreateInstance()
  File "/Users/dkheyman/dev/phileas/2016.6/lib/PerfKitBenchmarker/perfkitbenchmarker/providers/rackspace/rackspace_virtual_machine.py", line 249, in _CreateInstance
    'Following command caused the error: %s' % repr(create_cmd),)))
Error: Non-recoverable error has occurred: {u'error': u'Post https://iad.servers.api.rackspacecloud.com/v2/1010949/servers: dial tcp: lookup iad.servers.api.rackspacecloud.com on 172.16.1.1:53: read udp 172.16.1.1:53: i/o timeout'}
Following command caused the error: RackCLICommand(../lib/providers/Rackspace/rack servers instance create --name pkb-aec05f2c-3 --keypair pkb-aec05f2c-3 --flavor-id general1-1 --image-id 09de0a66-3156-48b4-90a5-1cf25a905207 --user-data /tmp/perfkitbenchmarker/runs/aec05f2c/user-data32uJqb --metadata owner=root --output json --profile phileas --region IAD)

2016-07-29 15:28:07,606 aec05f2c Thread-38 iperf(1/5) ping(2/5) INFO     Running: ../lib/providers/Rackspace/rack servers keypair delete --name pkb-aec05f2c-3 --output json --profile phileas --region IAD
2016-07-29 15:28:07,606 aec05f2c Thread-39 iperf(1/5) ping(2/5) INFO     Running: ../lib/providers/Rackspace/rack servers keypair delete --name pkb-aec05f2c-2 --output json --profile phileas --region IAD
2016-07-29 15:28:27,681 aec05f2c MainThread iperf(1/5) ping(2/5) ERROR    Benchmark 2/5 ping (UID: ping0) failed. Execution will continue.
2016-07-29 15:28:27,682 aec05f2c MainThread iperf(1/5) ping(2/5) fio(3/5) INFO     Provisioning resources for benchmark fio
2016-07-29 15:28:27,682 aec05f2c MainThread iperf(1/5) ping(2/5) fio(3/5) WARNING  Disk type name standard is deprecated and will be removed. Translating to boot for now.
2016-07-29 15:28:27,684 aec05f2c Thread-42 iperf(1/5) ping(2/5) fio(3/5) INFO     Running: ../lib/providers/Rackspace/rack servers keypair upload --name pkb-aec05f2c-4 --file /tmp/perfkitbenchmarker/runs/aec05f2c/perfkitbenchmarker_keyfile.pub --output json --profile phileas --region IAD
2016-07-29 15:28:47,704 aec05f2c Thread-42 iperf(1/5) ping(2/5) fio(3/5) INFO     Running: ../lib/providers/Rackspace/rack servers instance create --name pkb-aec05f2c-4 --keypair pkb-aec05f2c-4 --flavor-id general1-1 --image-id 09de0a66-3156-48b4-90a5-1cf25a905207 --user-data /tmp/perfkitbenchmarker/runs/aec05f2c/user-dataeilNvl --metadata owner=root --output json --profile phileas --region IAD
2016-07-29 15:29:07,777 aec05f2c MainThread iperf(1/5) ping(2/5) fio(3/5) ERROR    Exception occurred while calling PrepareVm(<BaseVirtualMachine [ip=None, internal_ip=None]>):
Traceback (most recent call last):
  File "/Users/dkheyman/dev/phileas/2016.6/lib/PerfKitBenchmarker/perfkitbenchmarker/background_tasks.py", line 234, in Run
    self.return_value = self.target(*self.args, **self.kwargs)
  File "/Users/dkheyman/dev/phileas/2016.6/lib/PerfKitBenchmarker/perfkitbenchmarker/benchmark_spec.py", line 341, in PrepareVm
    vm.Create()
  File "/Users/dkheyman/dev/phileas/2016.6/lib/PerfKitBenchmarker/perfkitbenchmarker/resource.py", line 150, in Create
    self._CreateResource()
  File "/Users/dkheyman/dev/phileas/2016.6/lib/PerfKitBenchmarker/perfkitbenchmarker/vm_util.py", line 239, in WrappedFunction
    return f(*args, **kwargs)
  File "/Users/dkheyman/dev/phileas/2016.6/lib/PerfKitBenchmarker/perfkitbenchmarker/resource.py", line 119, in _CreateResource
    self._Create()
  File "/Users/dkheyman/dev/phileas/2016.6/lib/PerfKitBenchmarker/perfkitbenchmarker/providers/rackspace/rackspace_virtual_machine.py", line 182, in _Create
    self._CreateInstance()
  File "/Users/dkheyman/dev/phileas/2016.6/lib/PerfKitBenchmarker/perfkitbenchmarker/providers/rackspace/rackspace_virtual_machine.py", line 249, in _CreateInstance
    'Following command caused the error: %s' % repr(create_cmd),)))
Error: Non-recoverable error has occurred: {u'error': u'Post https://iad.servers.api.rackspacecloud.com/v2/1010949/servers: dial tcp: lookup iad.servers.api.rackspacecloud.com on 172.16.1.1:53: read udp 172.16.1.1:53: i/o timeout'}
Following command caused the error: RackCLICommand(../lib/providers/Rackspace/rack servers instance create --name pkb-aec05f2c-4 --keypair pkb-aec05f2c-4 --flavor-id general1-1 --image-id 09de0a66-3156-48b4-90a5-1cf25a905207 --user-data /tmp/perfkitbenchmarker/runs/aec05f2c/user-dataeilNvl --metadata owner=root --output json --profile phileas --region IAD)

2016-07-29 15:29:07,781 aec05f2c MainThread iperf(1/5) ping(2/5) fio(3/5) ERROR    Error during benchmark fio
Traceback (most recent call last):
  File "/Users/dkheyman/dev/phileas/2016.6/lib/PerfKitBenchmarker/perfkitbenchmarker/pkb.py", line 470, in RunBenchmark
    DoProvisionPhase(benchmark_name, spec, detailed_timer)
  File "/Users/dkheyman/dev/phileas/2016.6/lib/PerfKitBenchmarker/perfkitbenchmarker/pkb.py", line 329, in DoProvisionPhase
    spec.Provision()
  File "/Users/dkheyman/dev/phileas/2016.6/lib/PerfKitBenchmarker/perfkitbenchmarker/benchmark_spec.py", line 264, in Provision
    vm_util.RunThreaded(self.PrepareVm, self.vms)
  File "/Users/dkheyman/dev/phileas/2016.6/lib/PerfKitBenchmarker/perfkitbenchmarker/background_tasks.py", line 613, in RunThreaded
    max_concurrency=max_concurrent_threads)
  File "/Users/dkheyman/dev/phileas/2016.6/lib/PerfKitBenchmarker/perfkitbenchmarker/background_tasks.py", line 557, in RunParallelThreads
    errors.VmUtil.ThreadException)
  File "/Users/dkheyman/dev/phileas/2016.6/lib/PerfKitBenchmarker/perfkitbenchmarker/background_tasks.py", line 532, in _RunParallelTasks
    '{0}{1}'.format(os.linesep, os.linesep.join(error_strings)))
ThreadException: The following exceptions occurred during parallel execution:
Exception occurred while calling PrepareVm(<BaseVirtualMachine [ip=None, internal_ip=None]>):
Traceback (most recent call last):
  File "/Users/dkheyman/dev/phileas/2016.6/lib/PerfKitBenchmarker/perfkitbenchmarker/background_tasks.py", line 234, in Run
    self.return_value = self.target(*self.args, **self.kwargs)
  File "/Users/dkheyman/dev/phileas/2016.6/lib/PerfKitBenchmarker/perfkitbenchmarker/benchmark_spec.py", line 341, in PrepareVm
    vm.Create()
  File "/Users/dkheyman/dev/phileas/2016.6/lib/PerfKitBenchmarker/perfkitbenchmarker/resource.py", line 150, in Create
    self._CreateResource()
  File "/Users/dkheyman/dev/phileas/2016.6/lib/PerfKitBenchmarker/perfkitbenchmarker/vm_util.py", line 239, in WrappedFunction
    return f(*args, **kwargs)
  File "/Users/dkheyman/dev/phileas/2016.6/lib/PerfKitBenchmarker/perfkitbenchmarker/resource.py", line 119, in _CreateResource
    self._Create()
  File "/Users/dkheyman/dev/phileas/2016.6/lib/PerfKitBenchmarker/perfkitbenchmarker/providers/rackspace/rackspace_virtual_machine.py", line 182, in _Create
    self._CreateInstance()
  File "/Users/dkheyman/dev/phileas/2016.6/lib/PerfKitBenchmarker/perfkitbenchmarker/providers/rackspace/rackspace_virtual_machine.py", line 249, in _CreateInstance
    'Following command caused the error: %s' % repr(create_cmd),)))
Error: Non-recoverable error has occurred: {u'error': u'Post https://iad.servers.api.rackspacecloud.com/v2/1010949/servers: dial tcp: lookup iad.servers.api.rackspacecloud.com on 172.16.1.1:53: read udp 172.16.1.1:53: i/o timeout'}
Following command caused the error: RackCLICommand(../lib/providers/Rackspace/rack servers instance create --name pkb-aec05f2c-4 --keypair pkb-aec05f2c-4 --flavor-id general1-1 --image-id 09de0a66-3156-48b4-90a5-1cf25a905207 --user-data /tmp/perfkitbenchmarker/runs/aec05f2c/user-dataeilNvl --metadata owner=root --output json --profile phileas --region IAD)

2016-07-29 15:29:07,782 aec05f2c Thread-45 iperf(1/5) ping(2/5) fio(3/5) INFO     Running: ../lib/providers/Rackspace/rack servers keypair delete --name pkb-aec05f2c-4 --output json --profile phileas --region IAD
2016-07-29 15:29:27,807 aec05f2c MainThread iperf(1/5) ping(2/5) fio(3/5) ERROR    Benchmark 3/5 fio (UID: fio0) failed. Execution will continue.
2016-07-29 15:29:27,808 aec05f2c MainThread iperf(1/5) ping(2/5) fio(3/5) coremark(4/5) INFO     Provisioning resources for benchmark coremark
2016-07-29 15:29:27,810 aec05f2c Thread-47 iperf(1/5) ping(2/5) fio(3/5) coremark(4/5) INFO     Running: ../lib/providers/Rackspace/rack servers keypair upload --name pkb-aec05f2c-5 --file /tmp/perfkitbenchmarker/runs/aec05f2c/perfkitbenchmarker_keyfile.pub --output json --profile phileas --region IAD
2016-07-29 15:29:47,831 aec05f2c Thread-47 iperf(1/5) ping(2/5) fio(3/5) coremark(4/5) INFO     Running: ../lib/providers/Rackspace/rack servers instance create --name pkb-aec05f2c-5 --keypair pkb-aec05f2c-5 --flavor-id general1-1 --image-id 09de0a66-3156-48b4-90a5-1cf25a905207 --user-data /tmp/perfkitbenchmarker/runs/aec05f2c/user-dataOeJz3Y --metadata owner=root --output json --profile phileas --region IAD
2016-07-29 15:30:07,864 aec05f2c MainThread iperf(1/5) ping(2/5) fio(3/5) coremark(4/5) ERROR    Exception occurred while calling PrepareVm(<BaseVirtualMachine [ip=None, internal_ip=None]>):
Traceback (most recent call last):
  File "/Users/dkheyman/dev/phileas/2016.6/lib/PerfKitBenchmarker/perfkitbenchmarker/background_tasks.py", line 234, in Run
    self.return_value = self.target(*self.args, **self.kwargs)
  File "/Users/dkheyman/dev/phileas/2016.6/lib/PerfKitBenchmarker/perfkitbenchmarker/benchmark_spec.py", line 341, in PrepareVm
    vm.Create()
  File "/Users/dkheyman/dev/phileas/2016.6/lib/PerfKitBenchmarker/perfkitbenchmarker/resource.py", line 150, in Create
    self._CreateResource()
  File "/Users/dkheyman/dev/phileas/2016.6/lib/PerfKitBenchmarker/perfkitbenchmarker/vm_util.py", line 239, in WrappedFunction
    return f(*args, **kwargs)
  File "/Users/dkheyman/dev/phileas/2016.6/lib/PerfKitBenchmarker/perfkitbenchmarker/resource.py", line 119, in _CreateResource
    self._Create()
  File "/Users/dkheyman/dev/phileas/2016.6/lib/PerfKitBenchmarker/perfkitbenchmarker/providers/rackspace/rackspace_virtual_machine.py", line 182, in _Create
    self._CreateInstance()
  File "/Users/dkheyman/dev/phileas/2016.6/lib/PerfKitBenchmarker/perfkitbenchmarker/providers/rackspace/rackspace_virtual_machine.py", line 249, in _CreateInstance
    'Following command caused the error: %s' % repr(create_cmd),)))
Error: Non-recoverable error has occurred: {u'error': u'Post https://iad.servers.api.rackspacecloud.com/v2/1010949/servers: dial tcp: lookup iad.servers.api.rackspacecloud.com on 172.16.1.1:53: read udp 172.16.1.1:53: i/o timeout'}
Following command caused the error: RackCLICommand(../lib/providers/Rackspace/rack servers instance create --name pkb-aec05f2c-5 --keypair pkb-aec05f2c-5 --flavor-id general1-1 --image-id 09de0a66-3156-48b4-90a5-1cf25a905207 --user-data /tmp/perfkitbenchmarker/runs/aec05f2c/user-dataOeJz3Y --metadata owner=root --output json --profile phileas --region IAD)

2016-07-29 15:30:07,868 aec05f2c MainThread iperf(1/5) ping(2/5) fio(3/5) coremark(4/5) ERROR    Error during benchmark coremark
Traceback (most recent call last):
  File "/Users/dkheyman/dev/phileas/2016.6/lib/PerfKitBenchmarker/perfkitbenchmarker/pkb.py", line 470, in RunBenchmark
    DoProvisionPhase(benchmark_name, spec, detailed_timer)
  File "/Users/dkheyman/dev/phileas/2016.6/lib/PerfKitBenchmarker/perfkitbenchmarker/pkb.py", line 329, in DoProvisionPhase
    spec.Provision()
  File "/Users/dkheyman/dev/phileas/2016.6/lib/PerfKitBenchmarker/perfkitbenchmarker/benchmark_spec.py", line 264, in Provision
    vm_util.RunThreaded(self.PrepareVm, self.vms)
  File "/Users/dkheyman/dev/phileas/2016.6/lib/PerfKitBenchmarker/perfkitbenchmarker/background_tasks.py", line 613, in RunThreaded
    max_concurrency=max_concurrent_threads)
  File "/Users/dkheyman/dev/phileas/2016.6/lib/PerfKitBenchmarker/perfkitbenchmarker/background_tasks.py", line 557, in RunParallelThreads
    errors.VmUtil.ThreadException)
  File "/Users/dkheyman/dev/phileas/2016.6/lib/PerfKitBenchmarker/perfkitbenchmarker/background_tasks.py", line 532, in _RunParallelTasks
    '{0}{1}'.format(os.linesep, os.linesep.join(error_strings)))
ThreadException: The following exceptions occurred during parallel execution:
Exception occurred while calling PrepareVm(<BaseVirtualMachine [ip=None, internal_ip=None]>):
Traceback (most recent call last):
  File "/Users/dkheyman/dev/phileas/2016.6/lib/PerfKitBenchmarker/perfkitbenchmarker/background_tasks.py", line 234, in Run
    self.return_value = self.target(*self.args, **self.kwargs)
  File "/Users/dkheyman/dev/phileas/2016.6/lib/PerfKitBenchmarker/perfkitbenchmarker/benchmark_spec.py", line 341, in PrepareVm
    vm.Create()
  File "/Users/dkheyman/dev/phileas/2016.6/lib/PerfKitBenchmarker/perfkitbenchmarker/resource.py", line 150, in Create
    self._CreateResource()
  File "/Users/dkheyman/dev/phileas/2016.6/lib/PerfKitBenchmarker/perfkitbenchmarker/vm_util.py", line 239, in WrappedFunction
    return f(*args, **kwargs)
  File "/Users/dkheyman/dev/phileas/2016.6/lib/PerfKitBenchmarker/perfkitbenchmarker/resource.py", line 119, in _CreateResource
    self._Create()
  File "/Users/dkheyman/dev/phileas/2016.6/lib/PerfKitBenchmarker/perfkitbenchmarker/providers/rackspace/rackspace_virtual_machine.py", line 182, in _Create
    self._CreateInstance()
  File "/Users/dkheyman/dev/phileas/2016.6/lib/PerfKitBenchmarker/perfkitbenchmarker/providers/rackspace/rackspace_virtual_machine.py", line 249, in _CreateInstance
    'Following command caused the error: %s' % repr(create_cmd),)))
Error: Non-recoverable error has occurred: {u'error': u'Post https://iad.servers.api.rackspacecloud.com/v2/1010949/servers: dial tcp: lookup iad.servers.api.rackspacecloud.com on 172.16.1.1:53: read udp 172.16.1.1:53: i/o timeout'}
Following command caused the error: RackCLICommand(../lib/providers/Rackspace/rack servers instance create --name pkb-aec05f2c-5 --keypair pkb-aec05f2c-5 --flavor-id general1-1 --image-id 09de0a66-3156-48b4-90a5-1cf25a905207 --user-data /tmp/perfkitbenchmarker/runs/aec05f2c/user-dataOeJz3Y --metadata owner=root --output json --profile phileas --region IAD)

2016-07-29 15:30:07,870 aec05f2c Thread-50 iperf(1/5) ping(2/5) fio(3/5) coremark(4/5) INFO     Running: ../lib/providers/Rackspace/rack servers keypair delete --name pkb-aec05f2c-5 --output json --profile phileas --region IAD
2016-07-29 16:44:56,161 aec05f2c MainThread iperf(1/5) ping(2/5) fio(3/5) coremark(4/5) ERROR    Benchmark 4/5 coremark (UID: coremark0) failed. Execution will continue.
2016-07-29 16:44:56,162 aec05f2c MainThread iperf(1/5) ping(2/5) fio(3/5) coremark(4/5) unixbench(5/5) INFO     Provisioning resources for benchmark unixbench
2016-07-29 16:44:56,162 aec05f2c MainThread iperf(1/5) ping(2/5) fio(3/5) coremark(4/5) unixbench(5/5) WARNING  Disk type name standard is deprecated and will be removed. Translating to boot for now.
2016-07-29 16:44:56,164 aec05f2c Thread-52 iperf(1/5) ping(2/5) fio(3/5) coremark(4/5) unixbench(5/5) INFO     Running: ../lib/providers/Rackspace/rack servers keypair upload --name pkb-aec05f2c-6 --file /tmp/perfkitbenchmarker/runs/aec05f2c/perfkitbenchmarker_keyfile.pub --output json --profile phileas --region IAD
2016-07-29 16:44:56,180 aec05f2c Thread-52 iperf(1/5) ping(2/5) fio(3/5) coremark(4/5) unixbench(5/5) INFO     Running: ../lib/providers/Rackspace/rack servers instance create --name pkb-aec05f2c-6 --keypair pkb-aec05f2c-6 --flavor-id general1-1 --image-id 09de0a66-3156-48b4-90a5-1cf25a905207 --user-data /tmp/perfkitbenchmarker/runs/aec05f2c/user-datactxhO7 --metadata owner=root --output json --profile phileas --region IAD
2016-07-29 16:44:56,198 aec05f2c MainThread iperf(1/5) ping(2/5) fio(3/5) coremark(4/5) unixbench(5/5) ERROR    Exception occurred while calling PrepareVm(<BaseVirtualMachine [ip=None, internal_ip=None]>):
Traceback (most recent call last):
  File "/Users/dkheyman/dev/phileas/2016.6/lib/PerfKitBenchmarker/perfkitbenchmarker/background_tasks.py", line 234, in Run
    self.return_value = self.target(*self.args, **self.kwargs)
  File "/Users/dkheyman/dev/phileas/2016.6/lib/PerfKitBenchmarker/perfkitbenchmarker/benchmark_spec.py", line 341, in PrepareVm
    vm.Create()
  File "/Users/dkheyman/dev/phileas/2016.6/lib/PerfKitBenchmarker/perfkitbenchmarker/resource.py", line 150, in Create
    self._CreateResource()
  File "/Users/dkheyman/dev/phileas/2016.6/lib/PerfKitBenchmarker/perfkitbenchmarker/vm_util.py", line 239, in WrappedFunction
    return f(*args, **kwargs)
  File "/Users/dkheyman/dev/phileas/2016.6/lib/PerfKitBenchmarker/perfkitbenchmarker/resource.py", line 119, in _CreateResource
    self._Create()
  File "/Users/dkheyman/dev/phileas/2016.6/lib/PerfKitBenchmarker/perfkitbenchmarker/providers/rackspace/rackspace_virtual_machine.py", line 182, in _Create
    self._CreateInstance()
  File "/Users/dkheyman/dev/phileas/2016.6/lib/PerfKitBenchmarker/perfkitbenchmarker/providers/rackspace/rackspace_virtual_machine.py", line 249, in _CreateInstance
    'Following command caused the error: %s' % repr(create_cmd),)))
Error: Non-recoverable error has occurred: {u'error': u'Post https://iad.servers.api.rackspacecloud.com/v2/1010949/servers: dial tcp: lookup iad.servers.api.rackspacecloud.com on 172.16.1.1:53: write udp 172.16.1.1:53: network is down'}
Following command caused the error: RackCLICommand(../lib/providers/Rackspace/rack servers instance create --name pkb-aec05f2c-6 --keypair pkb-aec05f2c-6 --flavor-id general1-1 --image-id 09de0a66-3156-48b4-90a5-1cf25a905207 --user-data /tmp/perfkitbenchmarker/runs/aec05f2c/user-datactxhO7 --metadata owner=root --output json --profile phileas --region IAD)

2016-07-29 16:44:56,201 aec05f2c MainThread iperf(1/5) ping(2/5) fio(3/5) coremark(4/5) unixbench(5/5) ERROR    Error during benchmark unixbench
Traceback (most recent call last):
  File "/Users/dkheyman/dev/phileas/2016.6/lib/PerfKitBenchmarker/perfkitbenchmarker/pkb.py", line 470, in RunBenchmark
    DoProvisionPhase(benchmark_name, spec, detailed_timer)
  File "/Users/dkheyman/dev/phileas/2016.6/lib/PerfKitBenchmarker/perfkitbenchmarker/pkb.py", line 329, in DoProvisionPhase
    spec.Provision()
  File "/Users/dkheyman/dev/phileas/2016.6/lib/PerfKitBenchmarker/perfkitbenchmarker/benchmark_spec.py", line 264, in Provision
    vm_util.RunThreaded(self.PrepareVm, self.vms)
  File "/Users/dkheyman/dev/phileas/2016.6/lib/PerfKitBenchmarker/perfkitbenchmarker/background_tasks.py", line 613, in RunThreaded
    max_concurrency=max_concurrent_threads)
  File "/Users/dkheyman/dev/phileas/2016.6/lib/PerfKitBenchmarker/perfkitbenchmarker/background_tasks.py", line 557, in RunParallelThreads
    errors.VmUtil.ThreadException)
  File "/Users/dkheyman/dev/phileas/2016.6/lib/PerfKitBenchmarker/perfkitbenchmarker/background_tasks.py", line 532, in _RunParallelTasks
    '{0}{1}'.format(os.linesep, os.linesep.join(error_strings)))
ThreadException: The following exceptions occurred during parallel execution:
Exception occurred while calling PrepareVm(<BaseVirtualMachine [ip=None, internal_ip=None]>):
Traceback (most recent call last):
  File "/Users/dkheyman/dev/phileas/2016.6/lib/PerfKitBenchmarker/perfkitbenchmarker/background_tasks.py", line 234, in Run
    self.return_value = self.target(*self.args, **self.kwargs)
  File "/Users/dkheyman/dev/phileas/2016.6/lib/PerfKitBenchmarker/perfkitbenchmarker/benchmark_spec.py", line 341, in PrepareVm
    vm.Create()
  File "/Users/dkheyman/dev/phileas/2016.6/lib/PerfKitBenchmarker/perfkitbenchmarker/resource.py", line 150, in Create
    self._CreateResource()
  File "/Users/dkheyman/dev/phileas/2016.6/lib/PerfKitBenchmarker/perfkitbenchmarker/vm_util.py", line 239, in WrappedFunction
    return f(*args, **kwargs)
  File "/Users/dkheyman/dev/phileas/2016.6/lib/PerfKitBenchmarker/perfkitbenchmarker/resource.py", line 119, in _CreateResource
    self._Create()
  File "/Users/dkheyman/dev/phileas/2016.6/lib/PerfKitBenchmarker/perfkitbenchmarker/providers/rackspace/rackspace_virtual_machine.py", line 182, in _Create
    self._CreateInstance()
  File "/Users/dkheyman/dev/phileas/2016.6/lib/PerfKitBenchmarker/perfkitbenchmarker/providers/rackspace/rackspace_virtual_machine.py", line 249, in _CreateInstance
    'Following command caused the error: %s' % repr(create_cmd),)))
Error: Non-recoverable error has occurred: {u'error': u'Post https://iad.servers.api.rackspacecloud.com/v2/1010949/servers: dial tcp: lookup iad.servers.api.rackspacecloud.com on 172.16.1.1:53: write udp 172.16.1.1:53: network is down'}
Following command caused the error: RackCLICommand(../lib/providers/Rackspace/rack servers instance create --name pkb-aec05f2c-6 --keypair pkb-aec05f2c-6 --flavor-id general1-1 --image-id 09de0a66-3156-48b4-90a5-1cf25a905207 --user-data /tmp/perfkitbenchmarker/runs/aec05f2c/user-datactxhO7 --metadata owner=root --output json --profile phileas --region IAD)

2016-07-29 16:44:56,203 aec05f2c Thread-55 iperf(1/5) ping(2/5) fio(3/5) coremark(4/5) unixbench(5/5) INFO     Running: ../lib/providers/Rackspace/rack servers keypair delete --name pkb-aec05f2c-6 --output json --profile phileas --region IAD
2016-07-29 16:44:56,222 aec05f2c MainThread iperf(1/5) ping(2/5) fio(3/5) coremark(4/5) unixbench(5/5) ERROR    Benchmark 5/5 unixbench (UID: unixbench0) failed. Execution will continue.
2016-07-29 16:44:56,222 aec05f2c MainThread iperf(1/5) ping(2/5) fio(3/5) coremark(4/5) unixbench(5/5) INFO     Benchmark run statuses:
-----------------------------
Name       UID         Status
-----------------------------
iperf      iperf0      FAILED
ping       ping0       FAILED
fio        fio0        FAILED
coremark   coremark0   FAILED
unixbench  unixbench0  FAILED
-----------------------------
Success rate: 0.00% (0/5)
2016-07-29 16:44:56,222 aec05f2c MainThread iperf(1/5) ping(2/5) fio(3/5) coremark(4/5) unixbench(5/5) INFO     Complete logs can be found at: /tmp/perfkitbenchmarker/runs/aec05f2c/pkb.log
